2024-12-14 16:17:53,445 - app.modules.dataset.routes - ERROR - Exception while create dataset data in local Destination path 'uploads/user_1/dataset_7/file1 (1).uvl' already exists
Traceback (most recent call last):
  File "/home/horacio/Escritorio/egc2/uvlhub/app/modules/dataset/routes.py", line 152, in create_dataset_draft
    dataset_service.move_feature_models(dataset)
  File "/home/horacio/Escritorio/egc2/uvlhub/app/modules/dataset/services.py", line 93, in move_feature_models
    shutil.move(os.path.join(source_dir, uvl_filename), dest_dir)
  File "/home/horacio/miniconda3/lib/python3.12/shutil.py", line 845, in move
    raise Error("Destination path '%s' already exists" % real_dst)
shutil.Error: Destination path 'uploads/user_1/dataset_7/file1 (1).uvl' already exists
2024-12-14 16:18:18,541 - app.modules.dataset.routes - ERROR - Exception while create dataset data in local Destination path 'uploads/user_1/dataset_8/file1 (2).uvl' already exists
Traceback (most recent call last):
  File "/home/horacio/Escritorio/egc2/uvlhub/app/modules/dataset/routes.py", line 152, in create_dataset_draft
    dataset_service.move_feature_models(dataset)
  File "/home/horacio/Escritorio/egc2/uvlhub/app/modules/dataset/services.py", line 93, in move_feature_models
    shutil.move(os.path.join(source_dir, uvl_filename), dest_dir)
  File "/home/horacio/miniconda3/lib/python3.12/shutil.py", line 845, in move
    raise Error("Destination path '%s' already exists" % real_dst)
shutil.Error: Destination path 'uploads/user_1/dataset_8/file1 (2).uvl' already exists
2024-12-14 16:19:56,381 - app.modules.dataset.routes - ERROR - Exception while create dataset data in local Destination path 'uploads/user_1/dataset_9/features12.uvl' already exists
Traceback (most recent call last):
  File "/home/horacio/Escritorio/egc2/uvlhub/app/modules/dataset/routes.py", line 152, in create_dataset_draft
    dataset_service.move_feature_models(dataset)
  File "/home/horacio/Escritorio/egc2/uvlhub/app/modules/dataset/services.py", line 93, in move_feature_models
    shutil.move(os.path.join(source_dir, uvl_filename), dest_dir)
  File "/home/horacio/miniconda3/lib/python3.12/shutil.py", line 845, in move
    raise Error("Destination path '%s' already exists" % real_dst)
shutil.Error: Destination path 'uploads/user_1/dataset_9/features12.uvl' already exists
2024-12-14 16:20:07,095 - app.modules.dataset.routes - ERROR - Exception while create dataset data in local Destination path 'uploads/user_1/dataset_10/features12.uvl' already exists
Traceback (most recent call last):
  File "/home/horacio/Escritorio/egc2/uvlhub/app/modules/dataset/routes.py", line 152, in create_dataset_draft
    dataset_service.move_feature_models(dataset)
  File "/home/horacio/Escritorio/egc2/uvlhub/app/modules/dataset/services.py", line 93, in move_feature_models
    shutil.move(os.path.join(source_dir, uvl_filename), dest_dir)
  File "/home/horacio/miniconda3/lib/python3.12/shutil.py", line 845, in move
    raise Error("Destination path '%s' already exists" % real_dst)
shutil.Error: Destination path 'uploads/user_1/dataset_10/features12.uvl' already exists
2024-12-14 16:21:44,082 - app.modules.dataset.routes - ERROR - Exception while create dataset data in local Destination path 'uploads/user_1/dataset_12/features12.uvl' already exists
Traceback (most recent call last):
  File "/home/horacio/Escritorio/egc2/uvlhub/app/modules/dataset/routes.py", line 152, in create_dataset_draft
    dataset_service.move_feature_models(dataset)
  File "/home/horacio/Escritorio/egc2/uvlhub/app/modules/dataset/services.py", line 93, in move_feature_models
    shutil.move(os.path.join(source_dir, uvl_filename), dest_dir)
  File "/home/horacio/miniconda3/lib/python3.12/shutil.py", line 845, in move
    raise Error("Destination path '%s' already exists" % real_dst)
shutil.Error: Destination path 'uploads/user_1/dataset_12/features12.uvl' already exists
2024-12-14 16:21:47,697 - app.modules.dataset.routes - ERROR - Exception while create dataset data in local [Errno 2] No such file or directory: 'uploads/temp/1/fileNew (1).uvl'
Traceback (most recent call last):
  File "/home/horacio/Escritorio/egc2/uvlhub/app/modules/dataset/routes.py", line 150, in create_dataset_draft
    dataset = dataset_service.create_from_form(form=form, current_user=current_user)
              ^^^^^^^^^^^^^^^^^^^^^^^^^^^^^^^^^^^^^^^^^^^^^^^^^^^^^^^^^^^^^^^^^^^^^^
  File "/home/horacio/Escritorio/egc2/uvlhub/app/modules/dataset/services.py", line 216, in create_from_form
    raise exc
  File "/home/horacio/Escritorio/egc2/uvlhub/app/modules/dataset/services.py", line 178, in create_from_form
    features += features_counter(uvl_file_path)
                ^^^^^^^^^^^^^^^^^^^^^^^^^^^^^^^
  File "/home/horacio/Escritorio/egc2/uvlhub/app/modules/dataset/services.py", line 47, in features_counter
    with open(uvl_file, 'r') as file:
         ^^^^^^^^^^^^^^^^^^^
FileNotFoundError: [Errno 2] No such file or directory: 'uploads/temp/1/fileNew (1).uvl'
2024-12-14 16:21:52,286 - app.modules.dataset.routes - ERROR - Exception while create dataset data in local [Errno 2] No such file or directory: 'uploads/temp/1/fileNew (1).uvl'
Traceback (most recent call last):
  File "/home/horacio/Escritorio/egc2/uvlhub/app/modules/dataset/routes.py", line 150, in create_dataset_draft
    dataset = dataset_service.create_from_form(form=form, current_user=current_user)
              ^^^^^^^^^^^^^^^^^^^^^^^^^^^^^^^^^^^^^^^^^^^^^^^^^^^^^^^^^^^^^^^^^^^^^^
  File "/home/horacio/Escritorio/egc2/uvlhub/app/modules/dataset/services.py", line 216, in create_from_form
    raise exc
  File "/home/horacio/Escritorio/egc2/uvlhub/app/modules/dataset/services.py", line 178, in create_from_form
    features += features_counter(uvl_file_path)
                ^^^^^^^^^^^^^^^^^^^^^^^^^^^^^^^
  File "/home/horacio/Escritorio/egc2/uvlhub/app/modules/dataset/services.py", line 47, in features_counter
    with open(uvl_file, 'r') as file:
         ^^^^^^^^^^^^^^^^^^^
FileNotFoundError: [Errno 2] No such file or directory: 'uploads/temp/1/fileNew (1).uvl'
2024-12-14 16:21:53,132 - app.modules.dataset.routes - ERROR - Exception while create dataset data in local [Errno 2] No such file or directory: 'uploads/temp/1/fileNew (1).uvl'
Traceback (most recent call last):
  File "/home/horacio/Escritorio/egc2/uvlhub/app/modules/dataset/routes.py", line 150, in create_dataset_draft
    dataset = dataset_service.create_from_form(form=form, current_user=current_user)
              ^^^^^^^^^^^^^^^^^^^^^^^^^^^^^^^^^^^^^^^^^^^^^^^^^^^^^^^^^^^^^^^^^^^^^^
  File "/home/horacio/Escritorio/egc2/uvlhub/app/modules/dataset/services.py", line 216, in create_from_form
    raise exc
  File "/home/horacio/Escritorio/egc2/uvlhub/app/modules/dataset/services.py", line 178, in create_from_form
    features += features_counter(uvl_file_path)
                ^^^^^^^^^^^^^^^^^^^^^^^^^^^^^^^
  File "/home/horacio/Escritorio/egc2/uvlhub/app/modules/dataset/services.py", line 47, in features_counter
    with open(uvl_file, 'r') as file:
         ^^^^^^^^^^^^^^^^^^^
FileNotFoundError: [Errno 2] No such file or directory: 'uploads/temp/1/fileNew (1).uvl'
2024-12-14 16:21:53,714 - app.modules.dataset.routes - ERROR - Exception while create dataset data in local [Errno 2] No such file or directory: 'uploads/temp/1/fileNew (1).uvl'
Traceback (most recent call last):
  File "/home/horacio/Escritorio/egc2/uvlhub/app/modules/dataset/routes.py", line 150, in create_dataset_draft
    dataset = dataset_service.create_from_form(form=form, current_user=current_user)
              ^^^^^^^^^^^^^^^^^^^^^^^^^^^^^^^^^^^^^^^^^^^^^^^^^^^^^^^^^^^^^^^^^^^^^^
  File "/home/horacio/Escritorio/egc2/uvlhub/app/modules/dataset/services.py", line 216, in create_from_form
    raise exc
  File "/home/horacio/Escritorio/egc2/uvlhub/app/modules/dataset/services.py", line 178, in create_from_form
    features += features_counter(uvl_file_path)
                ^^^^^^^^^^^^^^^^^^^^^^^^^^^^^^^
  File "/home/horacio/Escritorio/egc2/uvlhub/app/modules/dataset/services.py", line 47, in features_counter
    with open(uvl_file, 'r') as file:
         ^^^^^^^^^^^^^^^^^^^
FileNotFoundError: [Errno 2] No such file or directory: 'uploads/temp/1/fileNew (1).uvl'
2024-12-14 16:21:53,893 - app.modules.dataset.routes - ERROR - Exception while create dataset data in local [Errno 2] No such file or directory: 'uploads/temp/1/fileNew (1).uvl'
Traceback (most recent call last):
  File "/home/horacio/Escritorio/egc2/uvlhub/app/modules/dataset/routes.py", line 150, in create_dataset_draft
    dataset = dataset_service.create_from_form(form=form, current_user=current_user)
              ^^^^^^^^^^^^^^^^^^^^^^^^^^^^^^^^^^^^^^^^^^^^^^^^^^^^^^^^^^^^^^^^^^^^^^
  File "/home/horacio/Escritorio/egc2/uvlhub/app/modules/dataset/services.py", line 216, in create_from_form
    raise exc
  File "/home/horacio/Escritorio/egc2/uvlhub/app/modules/dataset/services.py", line 178, in create_from_form
    features += features_counter(uvl_file_path)
                ^^^^^^^^^^^^^^^^^^^^^^^^^^^^^^^
  File "/home/horacio/Escritorio/egc2/uvlhub/app/modules/dataset/services.py", line 47, in features_counter
    with open(uvl_file, 'r') as file:
         ^^^^^^^^^^^^^^^^^^^
FileNotFoundError: [Errno 2] No such file or directory: 'uploads/temp/1/fileNew (1).uvl'
