2024-12-14 15:06:12,415 - app.modules.dataset.routes - ERROR - Exception while create dataset data in local Destination path 'uploads/user_1/dataset_5/file1.uvl' already exists
Traceback (most recent call last):
  File "/home/horacio/Escritorio/egc2/uvlhub/app/modules/dataset/routes.py", line 85, in create_dataset
    dataset_service.move_feature_models(dataset)
  File "/home/horacio/Escritorio/egc2/uvlhub/app/modules/dataset/services.py", line 93, in move_feature_models
    shutil.move(os.path.join(source_dir, uvl_filename), dest_dir)
  File "/home/horacio/miniconda3/lib/python3.12/shutil.py", line 845, in move
    raise Error("Destination path '%s' already exists" % real_dst)
shutil.Error: Destination path 'uploads/user_1/dataset_5/file1.uvl' already exists
2024-12-14 15:09:38,475 - app.modules.dataset.routes - ERROR - Exception while create dataset data in local Destination path 'uploads/user_1/dataset_6/file1 (1).uvl' already exists
Traceback (most recent call last):
  File "/home/horacio/Escritorio/egc2/uvlhub/app/modules/dataset/routes.py", line 85, in create_dataset
    dataset_service.move_feature_models(dataset)
  File "/home/horacio/Escritorio/egc2/uvlhub/app/modules/dataset/services.py", line 93, in move_feature_models
    shutil.move(os.path.join(source_dir, uvl_filename), dest_dir)
  File "/home/horacio/miniconda3/lib/python3.12/shutil.py", line 845, in move
    raise Error("Destination path '%s' already exists" % real_dst)
shutil.Error: Destination path 'uploads/user_1/dataset_6/file1 (1).uvl' already exists
2024-12-14 15:13:04,415 - app.modules.dataset.routes - ERROR - Exception while create dataset data in local Destination path 'uploads/user_1/dataset_5/file1.uvl' already exists
Traceback (most recent call last):
  File "/home/horacio/Escritorio/egc2/uvlhub/app/modules/dataset/routes.py", line 85, in create_dataset
    dataset_service.move_feature_models(dataset)
  File "/home/horacio/Escritorio/egc2/uvlhub/app/modules/dataset/services.py", line 93, in move_feature_models
    shutil.move(os.path.join(source_dir, uvl_filename), dest_dir)
  File "/home/horacio/miniconda3/lib/python3.12/shutil.py", line 845, in move
    raise Error("Destination path '%s' already exists" % real_dst)
shutil.Error: Destination path 'uploads/user_1/dataset_5/file1.uvl' already exists
2024-12-14 15:26:14,183 - app.modules.dataset.routes - ERROR - Exception while create dataset data in local Destination path 'uploads/user_1/dataset_6/file1 (1).uvl' already exists
Traceback (most recent call last):
  File "/home/horacio/Escritorio/egc2/uvlhub/app/modules/dataset/routes.py", line 152, in create_dataset_draft
    dataset_service.move_feature_models(dataset)
  File "/home/horacio/Escritorio/egc2/uvlhub/app/modules/dataset/services.py", line 93, in move_feature_models
    shutil.move(os.path.join(source_dir, uvl_filename), dest_dir)
  File "/home/horacio/miniconda3/lib/python3.12/shutil.py", line 845, in move
    raise Error("Destination path '%s' already exists" % real_dst)
shutil.Error: Destination path 'uploads/user_1/dataset_6/file1 (1).uvl' already exists
2024-12-14 15:33:54,556 - app.modules.dataset.routes - ERROR - Exception while create dataset data in local Destination path 'uploads/user_1/dataset_7/file1 (2).uvl' already exists
Traceback (most recent call last):
  File "/home/horacio/Escritorio/egc2/uvlhub/app/modules/dataset/routes.py", line 152, in create_dataset_draft
    dataset_service.move_feature_models(dataset)
  File "/home/horacio/Escritorio/egc2/uvlhub/app/modules/dataset/services.py", line 93, in move_feature_models
    shutil.move(os.path.join(source_dir, uvl_filename), dest_dir)
  File "/home/horacio/miniconda3/lib/python3.12/shutil.py", line 845, in move
    raise Error("Destination path '%s' already exists" % real_dst)
shutil.Error: Destination path 'uploads/user_1/dataset_7/file1 (2).uvl' already exists
2024-12-14 15:44:25,221 - app.modules.dataset.routes - ERROR - Exception while create dataset data in local Destination path 'uploads/user_1/dataset_6/file1.uvl' already exists
Traceback (most recent call last):
  File "/home/horacio/Escritorio/egc2/uvlhub/app/modules/dataset/routes.py", line 152, in create_dataset_draft
    dataset_service.move_feature_models(dataset)
  File "/home/horacio/Escritorio/egc2/uvlhub/app/modules/dataset/services.py", line 93, in move_feature_models
    shutil.move(os.path.join(source_dir, uvl_filename), dest_dir)
  File "/home/horacio/miniconda3/lib/python3.12/shutil.py", line 845, in move
    raise Error("Destination path '%s' already exists" % real_dst)
shutil.Error: Destination path 'uploads/user_1/dataset_6/file1.uvl' already exists
2024-12-14 15:47:14,701 - app.modules.dataset.routes - ERROR - Exception while create dataset data in local Destination path 'uploads/user_1/dataset_9/file1.uvl' already exists
Traceback (most recent call last):
  File "/home/horacio/Escritorio/egc2/uvlhub/app/modules/dataset/routes.py", line 85, in create_dataset
    dataset_service.move_feature_models(dataset)
  File "/home/horacio/Escritorio/egc2/uvlhub/app/modules/dataset/services.py", line 93, in move_feature_models
    shutil.move(os.path.join(source_dir, uvl_filename), dest_dir)
  File "/home/horacio/miniconda3/lib/python3.12/shutil.py", line 845, in move
    raise Error("Destination path '%s' already exists" % real_dst)
shutil.Error: Destination path 'uploads/user_1/dataset_9/file1.uvl' already exists
2024-12-14 15:47:56,034 - app.modules.dataset.routes - ERROR - Exception while create dataset data in local Destination path 'uploads/user_1/dataset_6/file1 (1).uvl' already exists
Traceback (most recent call last):
  File "/home/horacio/Escritorio/egc2/uvlhub/app/modules/dataset/routes.py", line 152, in create_dataset_draft
    dataset_service.move_feature_models(dataset)
  File "/home/horacio/Escritorio/egc2/uvlhub/app/modules/dataset/services.py", line 93, in move_feature_models
    shutil.move(os.path.join(source_dir, uvl_filename), dest_dir)
  File "/home/horacio/miniconda3/lib/python3.12/shutil.py", line 845, in move
    raise Error("Destination path '%s' already exists" % real_dst)
shutil.Error: Destination path 'uploads/user_1/dataset_6/file1 (1).uvl' already exists
2024-12-14 15:48:09,709 - app.modules.dataset.routes - ERROR - Exception while create dataset data in local Destination path 'uploads/user_1/dataset_7/file1 (2).uvl' already exists
Traceback (most recent call last):
  File "/home/horacio/Escritorio/egc2/uvlhub/app/modules/dataset/routes.py", line 152, in create_dataset_draft
    dataset_service.move_feature_models(dataset)
  File "/home/horacio/Escritorio/egc2/uvlhub/app/modules/dataset/services.py", line 93, in move_feature_models
    shutil.move(os.path.join(source_dir, uvl_filename), dest_dir)
  File "/home/horacio/miniconda3/lib/python3.12/shutil.py", line 845, in move
    raise Error("Destination path '%s' already exists" % real_dst)
shutil.Error: Destination path 'uploads/user_1/dataset_7/file1 (2).uvl' already exists
2024-12-14 15:48:47,221 - app.modules.dataset.routes - ERROR - Exception while create dataset data in local Destination path 'uploads/user_1/dataset_9/file1.uvl' already exists
Traceback (most recent call last):
  File "/home/horacio/Escritorio/egc2/uvlhub/app/modules/dataset/routes.py", line 85, in create_dataset
    dataset_service.move_feature_models(dataset)
  File "/home/horacio/Escritorio/egc2/uvlhub/app/modules/dataset/services.py", line 93, in move_feature_models
    shutil.move(os.path.join(source_dir, uvl_filename), dest_dir)
  File "/home/horacio/miniconda3/lib/python3.12/shutil.py", line 845, in move
    raise Error("Destination path '%s' already exists" % real_dst)
shutil.Error: Destination path 'uploads/user_1/dataset_9/file1.uvl' already exists
2024-12-14 15:49:38,856 - app.modules.dataset.routes - ERROR - Exception while create dataset data in local Destination path 'uploads/user_1/dataset_10/file2.uvl' already exists
Traceback (most recent call last):
  File "/home/horacio/Escritorio/egc2/uvlhub/app/modules/dataset/routes.py", line 152, in create_dataset_draft
    dataset_service.move_feature_models(dataset)
  File "/home/horacio/Escritorio/egc2/uvlhub/app/modules/dataset/services.py", line 93, in move_feature_models
    shutil.move(os.path.join(source_dir, uvl_filename), dest_dir)
  File "/home/horacio/miniconda3/lib/python3.12/shutil.py", line 845, in move
    raise Error("Destination path '%s' already exists" % real_dst)
shutil.Error: Destination path 'uploads/user_1/dataset_10/file2.uvl' already exists
2024-12-14 15:59:38,438 - app.modules.dataset.routes - ERROR - Exception while create dataset data in local Destination path 'uploads/user_1/dataset_6/file1.uvl' already exists
Traceback (most recent call last):
  File "/home/horacio/Escritorio/egc2/uvlhub/app/modules/dataset/routes.py", line 152, in create_dataset_draft
    dataset_service.move_feature_models(dataset)
  File "/home/horacio/Escritorio/egc2/uvlhub/app/modules/dataset/services.py", line 93, in move_feature_models
    shutil.move(os.path.join(source_dir, uvl_filename), dest_dir)
  File "/home/horacio/miniconda3/lib/python3.12/shutil.py", line 845, in move
    raise Error("Destination path '%s' already exists" % real_dst)
shutil.Error: Destination path 'uploads/user_1/dataset_6/file1.uvl' already exists
2024-12-14 16:00:49,342 - app.modules.dataset.routes - ERROR - Exception while create dataset data in local Destination path 'uploads/user_1/dataset_7/file1 (1).uvl' already exists
Traceback (most recent call last):
  File "/home/horacio/Escritorio/egc2/uvlhub/app/modules/dataset/routes.py", line 152, in create_dataset_draft
    dataset_service.move_feature_models(dataset)
  File "/home/horacio/Escritorio/egc2/uvlhub/app/modules/dataset/services.py", line 93, in move_feature_models
    shutil.move(os.path.join(source_dir, uvl_filename), dest_dir)
  File "/home/horacio/miniconda3/lib/python3.12/shutil.py", line 845, in move
    raise Error("Destination path '%s' already exists" % real_dst)
shutil.Error: Destination path 'uploads/user_1/dataset_7/file1 (1).uvl' already exists
